[2025-04-09T16:18:42.213+0000] {local_task_job_runner.py:123} INFO - ::group::Pre task execution logs
[2025-04-09T16:18:42.425+0000] {taskinstance.py:2614} INFO - Dependencies all met for dep_context=non-requeueable deps ti=<TaskInstance: et_extract_load.insert_transformed_to_core manual__2025-04-09T16:18:33.004297+00:00 [queued]>
[2025-04-09T16:18:42.442+0000] {taskinstance.py:2614} INFO - Dependencies all met for dep_context=requeueable deps ti=<TaskInstance: et_extract_load.insert_transformed_to_core manual__2025-04-09T16:18:33.004297+00:00 [queued]>
[2025-04-09T16:18:42.443+0000] {taskinstance.py:2867} INFO - Starting attempt 1 of 1
[2025-04-09T16:18:42.451+0000] {taskinstance.py:2890} INFO - Executing <Task(PythonOperator): insert_transformed_to_core> on 2025-04-09 16:18:33.004297+00:00
[2025-04-09T16:18:42.459+0000] {warnings.py:112} WARNING - /home/***/.local/lib/python3.12/site-packages/***/task/task_runner/standard_task_runner.py:70: DeprecationWarning: This process (pid=24678) is multi-threaded, use of fork() may lead to deadlocks in the child.
  pid = os.fork()

[2025-04-09T16:18:42.460+0000] {standard_task_runner.py:72} INFO - Started process 24679 to run task
[2025-04-09T16:18:42.461+0000] {standard_task_runner.py:104} INFO - Running: ['***', 'tasks', 'run', 'et_extract_load', 'insert_transformed_to_core', 'manual__2025-04-09T16:18:33.004297+00:00', '--job-id', '68', '--raw', '--subdir', 'DAGS_FOLDER/etl_extract_load.py', '--cfg-path', '/tmp/tmpo6m00zhc']
[2025-04-09T16:18:42.462+0000] {standard_task_runner.py:105} INFO - Job 68: Subtask insert_transformed_to_core
[2025-04-09T16:18:42.507+0000] {task_command.py:467} INFO - Running <TaskInstance: et_extract_load.insert_transformed_to_core manual__2025-04-09T16:18:33.004297+00:00 [running]> on host 8bfd2e589ccf
[2025-04-09T16:18:42.571+0000] {taskinstance.py:3134} INFO - Exporting env vars: AIRFLOW_CTX_DAG_OWNER='***' AIRFLOW_CTX_DAG_ID='et_extract_load' AIRFLOW_CTX_TASK_ID='insert_transformed_to_core' AIRFLOW_CTX_EXECUTION_DATE='2025-04-09T16:18:33.004297+00:00' AIRFLOW_CTX_TRY_NUMBER='1' AIRFLOW_CTX_DAG_RUN_ID='manual__2025-04-09T16:18:33.004297+00:00'
[2025-04-09T16:18:42.573+0000] {logging_mixin.py:190} INFO - Task instance is in running state
[2025-04-09T16:18:42.574+0000] {logging_mixin.py:190} INFO -  Previous state of the Task instance: queued
[2025-04-09T16:18:42.574+0000] {logging_mixin.py:190} INFO - Current task name:insert_transformed_to_core state:running start_date:2025-04-09 16:18:42.436413+00:00
[2025-04-09T16:18:42.575+0000] {logging_mixin.py:190} INFO - Dag name:et_extract_load and current dag run status:running
[2025-04-09T16:18:42.575+0000] {taskinstance.py:732} INFO - ::endgroup::
[2025-04-09T16:18:42.582+0000] {base.py:84} INFO - Retrieving connection 'PostgresSQL_connection_1'
[2025-04-09T16:18:42.594+0000] {warnings.py:112} WARNING - /home/***/.local/lib/python3.12/site-packages/***/providers/common/sql/hooks/sql.py:287: UserWarning: pandas only supports SQLAlchemy connectable (engine/connection) or database string URI or sqlite3 DBAPI2 connection. Other DBAPI2 objects are not tested. Please consider using SQLAlchemy.
  return psql.read_sql(sql, con=conn, params=parameters, **kwargs)

[2025-04-09T16:18:42.671+0000] {sql.py:511} INFO - Running statement: 
        INSERT INTO "Core"."dim_product" (product_id, product_name, category, subcategory, brand)
        VALUES (%s, %s, %s, %s, %s)
        , parameters: ('P0000', 'serum', 'Fruits & Vegetables', 'Herbs & Seasonings', 'Livon')
[2025-04-09T16:18:42.679+0000] {taskinstance.py:3313} ERROR - Task failed with exception
Traceback (most recent call last):
  File "/home/airflow/.local/lib/python3.12/site-packages/airflow/models/taskinstance.py", line 768, in _execute_task
    result = _execute_callable(context=context, **execute_callable_kwargs)
             ^^^^^^^^^^^^^^^^^^^^^^^^^^^^^^^^^^^^^^^^^^^^^^^^^^^^^^^^^^^^^
  File "/home/airflow/.local/lib/python3.12/site-packages/airflow/models/taskinstance.py", line 734, in _execute_callable
    return ExecutionCallableRunner(
           ^^^^^^^^^^^^^^^^^^^^^^^^
  File "/home/airflow/.local/lib/python3.12/site-packages/airflow/utils/operator_helpers.py", line 252, in run
    return self.func(*args, **kwargs)
           ^^^^^^^^^^^^^^^^^^^^^^^^^^
  File "/home/airflow/.local/lib/python3.12/site-packages/airflow/models/baseoperator.py", line 424, in wrapper
    return func(self, *args, **kwargs)
           ^^^^^^^^^^^^^^^^^^^^^^^^^^^
  File "/home/airflow/.local/lib/python3.12/site-packages/airflow/operators/python.py", line 238, in execute
    return_value = self.execute_callable()
                   ^^^^^^^^^^^^^^^^^^^^^^^
  File "/home/airflow/.local/lib/python3.12/site-packages/airflow/operators/python.py", line 256, in execute_callable
    return runner.run(*self.op_args, **self.op_kwargs)
           ^^^^^^^^^^^^^^^^^^^^^^^^^^^^^^^^^^^^^^^^^^^
  File "/home/airflow/.local/lib/python3.12/site-packages/airflow/utils/operator_helpers.py", line 252, in run
    return self.func(*args, **kwargs)
           ^^^^^^^^^^^^^^^^^^^^^^^^^^
  File "/opt/airflow/dags/etl_extract_load.py", line 109, in insert_transformed_to_core
    pg_hook.run(insert_sql, parameters=(row['product_id'], row['product_name'], row['category'], row['subcategory'], row['brand']))
  File "/home/airflow/.local/lib/python3.12/site-packages/airflow/providers/common/sql/hooks/sql.py", line 467, in run
    self._run_command(cur, sql_statement, parameters)
  File "/home/airflow/.local/lib/python3.12/site-packages/airflow/providers/common/sql/hooks/sql.py", line 514, in _run_command
    cur.execute(sql_statement, parameters)
psycopg2.errors.UndefinedTable: relation "Core.dim_product" does not exist
LINE 2:         INSERT INTO "Core"."dim_product" (product_id, produc...
                            ^

[2025-04-09T16:18:42.714+0000] {logging_mixin.py:190} INFO - Task instance in failure state
[2025-04-09T16:18:42.716+0000] {logging_mixin.py:190} INFO - Task start:2025-04-09 16:18:42.436413+00:00 end:2025-04-09 16:18:42.713737+00:00 duration:0.277324
[2025-04-09T16:18:42.717+0000] {logging_mixin.py:190} INFO - Task:<Task(PythonOperator): insert_transformed_to_core> dag:<DAG: et_extract_load> dagrun:<DagRun et_extract_load @ 2025-04-09 16:18:33.004297+00:00: manual__2025-04-09T16:18:33.004297+00:00, state:running, queued_at: 2025-04-09 16:18:33.024044+00:00. externally triggered: True>
[2025-04-09T16:18:42.726+0000] {logging_mixin.py:190} INFO - Failure caused by relation "Core.dim_product" does not exist
LINE 2:         INSERT INTO "Core"."dim_product" (product_id, produc...
                            ^
[2025-04-09T16:18:42.727+0000] {taskinstance.py:1226} INFO - Marking task as FAILED. dag_id=et_extract_load, task_id=insert_transformed_to_core, run_id=manual__2025-04-09T16:18:33.004297+00:00, execution_date=20250409T161833, start_date=20250409T161842, end_date=20250409T161842
[2025-04-09T16:18:42.762+0000] {taskinstance.py:341} INFO - ::group::Post task execution logs
[2025-04-09T16:18:42.763+0000] {standard_task_runner.py:124} ERROR - Failed to execute job 68 for task insert_transformed_to_core (relation "Core.dim_product" does not exist
LINE 2:         INSERT INTO "Core"."dim_product" (product_id, produc...
                            ^
; 24679)
Traceback (most recent call last):
  File "/home/airflow/.local/lib/python3.12/site-packages/airflow/task/task_runner/standard_task_runner.py", line 117, in _start_by_fork
    ret = args.func(args, dag=self.dag)
          ^^^^^^^^^^^^^^^^^^^^^^^^^^^^^
  File "/home/airflow/.local/lib/python3.12/site-packages/airflow/cli/cli_config.py", line 49, in command
    return func(*args, **kwargs)
           ^^^^^^^^^^^^^^^^^^^^^
  File "/home/airflow/.local/lib/python3.12/site-packages/airflow/utils/cli.py", line 116, in wrapper
    return f(*args, **kwargs)
           ^^^^^^^^^^^^^^^^^^
  File "/home/airflow/.local/lib/python3.12/site-packages/airflow/cli/commands/task_command.py", line 483, in task_run
    task_return_code = _run_task_by_selected_method(args, _dag, ti)
                       ^^^^^^^^^^^^^^^^^^^^^^^^^^^^^^^^^^^^^^^^^^^^
  File "/home/airflow/.local/lib/python3.12/site-packages/airflow/cli/commands/task_command.py", line 256, in _run_task_by_selected_method
    return _run_raw_task(args, ti)
           ^^^^^^^^^^^^^^^^^^^^^^^
  File "/home/airflow/.local/lib/python3.12/site-packages/airflow/cli/commands/task_command.py", line 341, in _run_raw_task
    return ti._run_raw_task(
           ^^^^^^^^^^^^^^^^^
  File "/home/airflow/.local/lib/python3.12/site-packages/airflow/utils/session.py", line 97, in wrapper
    return func(*args, session=session, **kwargs)
           ^^^^^^^^^^^^^^^^^^^^^^^^^^^^^^^^^^^^^^
  File "/home/airflow/.local/lib/python3.12/site-packages/airflow/models/taskinstance.py", line 3006, in _run_raw_task
    return _run_raw_task(
           ^^^^^^^^^^^^^^
  File "/home/airflow/.local/lib/python3.12/site-packages/airflow/models/taskinstance.py", line 274, in _run_raw_task
    TaskInstance._execute_task_with_callbacks(
  File "/home/airflow/.local/lib/python3.12/site-packages/airflow/models/taskinstance.py", line 3161, in _execute_task_with_callbacks
    result = self._execute_task(context, task_orig)
             ^^^^^^^^^^^^^^^^^^^^^^^^^^^^^^^^^^^^^^
  File "/home/airflow/.local/lib/python3.12/site-packages/airflow/models/taskinstance.py", line 3185, in _execute_task
    return _execute_task(self, context, task_orig)
           ^^^^^^^^^^^^^^^^^^^^^^^^^^^^^^^^^^^^^^^
  File "/home/airflow/.local/lib/python3.12/site-packages/airflow/models/taskinstance.py", line 768, in _execute_task
    result = _execute_callable(context=context, **execute_callable_kwargs)
             ^^^^^^^^^^^^^^^^^^^^^^^^^^^^^^^^^^^^^^^^^^^^^^^^^^^^^^^^^^^^^
  File "/home/airflow/.local/lib/python3.12/site-packages/airflow/models/taskinstance.py", line 734, in _execute_callable
    return ExecutionCallableRunner(
           ^^^^^^^^^^^^^^^^^^^^^^^^
  File "/home/airflow/.local/lib/python3.12/site-packages/airflow/utils/operator_helpers.py", line 252, in run
    return self.func(*args, **kwargs)
           ^^^^^^^^^^^^^^^^^^^^^^^^^^
  File "/home/airflow/.local/lib/python3.12/site-packages/airflow/models/baseoperator.py", line 424, in wrapper
    return func(self, *args, **kwargs)
           ^^^^^^^^^^^^^^^^^^^^^^^^^^^
  File "/home/airflow/.local/lib/python3.12/site-packages/airflow/operators/python.py", line 238, in execute
    return_value = self.execute_callable()
                   ^^^^^^^^^^^^^^^^^^^^^^^
  File "/home/airflow/.local/lib/python3.12/site-packages/airflow/operators/python.py", line 256, in execute_callable
    return runner.run(*self.op_args, **self.op_kwargs)
           ^^^^^^^^^^^^^^^^^^^^^^^^^^^^^^^^^^^^^^^^^^^
  File "/home/airflow/.local/lib/python3.12/site-packages/airflow/utils/operator_helpers.py", line 252, in run
    return self.func(*args, **kwargs)
           ^^^^^^^^^^^^^^^^^^^^^^^^^^
  File "/opt/airflow/dags/etl_extract_load.py", line 109, in insert_transformed_to_core
    pg_hook.run(insert_sql, parameters=(row['product_id'], row['product_name'], row['category'], row['subcategory'], row['brand']))
  File "/home/airflow/.local/lib/python3.12/site-packages/airflow/providers/common/sql/hooks/sql.py", line 467, in run
    self._run_command(cur, sql_statement, parameters)
  File "/home/airflow/.local/lib/python3.12/site-packages/airflow/providers/common/sql/hooks/sql.py", line 514, in _run_command
    cur.execute(sql_statement, parameters)
psycopg2.errors.UndefinedTable: relation "Core.dim_product" does not exist
LINE 2:         INSERT INTO "Core"."dim_product" (product_id, produc...
                            ^

[2025-04-09T16:18:42.804+0000] {local_task_job_runner.py:266} INFO - Task exited with return code 1
[2025-04-09T16:18:42.837+0000] {taskinstance.py:3901} INFO - 0 downstream tasks scheduled from follow-on schedule check
[2025-04-09T16:18:42.860+0000] {local_task_job_runner.py:245} INFO - ::endgroup::
