[2025-04-04T11:25:09.767+0000] {local_task_job_runner.py:123} INFO - ::group::Pre task execution logs
[2025-04-04T11:25:09.782+0000] {taskinstance.py:2614} INFO - Dependencies all met for dep_context=non-requeueable deps ti=<TaskInstance: et_extract_load.query_public_table manual__2025-04-04T11:25:04.300102+00:00 [queued]>
[2025-04-04T11:25:09.787+0000] {taskinstance.py:2614} INFO - Dependencies all met for dep_context=requeueable deps ti=<TaskInstance: et_extract_load.query_public_table manual__2025-04-04T11:25:04.300102+00:00 [queued]>
[2025-04-04T11:25:09.788+0000] {taskinstance.py:2867} INFO - Starting attempt 1 of 1
[2025-04-04T11:25:09.798+0000] {taskinstance.py:2890} INFO - Executing <Task(PythonOperator): query_public_table> on 2025-04-04 11:25:04.300102+00:00
[2025-04-04T11:25:09.825+0000] {warnings.py:112} WARNING - /home/***/.local/lib/python3.12/site-packages/***/task/task_runner/standard_task_runner.py:70: DeprecationWarning: This process (pid=1508) is multi-threaded, use of fork() may lead to deadlocks in the child.
  pid = os.fork()

[2025-04-04T11:25:09.830+0000] {standard_task_runner.py:72} INFO - Started process 1509 to run task
[2025-04-04T11:25:09.830+0000] {standard_task_runner.py:104} INFO - Running: ['***', 'tasks', 'run', 'et_extract_load', 'query_public_table', 'manual__2025-04-04T11:25:04.300102+00:00', '--job-id', '35', '--raw', '--subdir', 'DAGS_FOLDER/etl_extract_load.py', '--cfg-path', '/tmp/tmptbtxccr_']
[2025-04-04T11:25:09.832+0000] {standard_task_runner.py:105} INFO - Job 35: Subtask query_public_table
[2025-04-04T11:25:10.266+0000] {task_command.py:467} INFO - Running <TaskInstance: et_extract_load.query_public_table manual__2025-04-04T11:25:04.300102+00:00 [running]> on host 8bfd2e589ccf
[2025-04-04T11:25:10.328+0000] {taskinstance.py:3134} INFO - Exporting env vars: AIRFLOW_CTX_DAG_OWNER='***' AIRFLOW_CTX_DAG_ID='et_extract_load' AIRFLOW_CTX_TASK_ID='query_public_table' AIRFLOW_CTX_EXECUTION_DATE='2025-04-04T11:25:04.300102+00:00' AIRFLOW_CTX_TRY_NUMBER='1' AIRFLOW_CTX_DAG_RUN_ID='manual__2025-04-04T11:25:04.300102+00:00'
[2025-04-04T11:25:10.329+0000] {logging_mixin.py:190} INFO - Task instance is in running state
[2025-04-04T11:25:10.329+0000] {logging_mixin.py:190} INFO -  Previous state of the Task instance: queued
[2025-04-04T11:25:10.329+0000] {logging_mixin.py:190} INFO - Current task name:query_public_table state:running start_date:2025-04-04 11:25:09.782920+00:00
[2025-04-04T11:25:10.329+0000] {logging_mixin.py:190} INFO - Dag name:et_extract_load and current dag run status:running
[2025-04-04T11:25:10.330+0000] {taskinstance.py:732} INFO - ::endgroup::
[2025-04-04T11:25:10.341+0000] {base.py:84} INFO - Retrieving connection 'PostgresSQL_connection_1'
[2025-04-04T11:25:10.384+0000] {taskinstance.py:3313} ERROR - Task failed with exception
Traceback (most recent call last):
  File "/home/airflow/.local/lib/python3.12/site-packages/airflow/models/taskinstance.py", line 768, in _execute_task
    result = _execute_callable(context=context, **execute_callable_kwargs)
             ^^^^^^^^^^^^^^^^^^^^^^^^^^^^^^^^^^^^^^^^^^^^^^^^^^^^^^^^^^^^^
  File "/home/airflow/.local/lib/python3.12/site-packages/airflow/models/taskinstance.py", line 734, in _execute_callable
    return ExecutionCallableRunner(
           ^^^^^^^^^^^^^^^^^^^^^^^^
  File "/home/airflow/.local/lib/python3.12/site-packages/airflow/utils/operator_helpers.py", line 252, in run
    return self.func(*args, **kwargs)
           ^^^^^^^^^^^^^^^^^^^^^^^^^^
  File "/home/airflow/.local/lib/python3.12/site-packages/airflow/models/baseoperator.py", line 424, in wrapper
    return func(self, *args, **kwargs)
           ^^^^^^^^^^^^^^^^^^^^^^^^^^^
  File "/home/airflow/.local/lib/python3.12/site-packages/airflow/operators/python.py", line 238, in execute
    return_value = self.execute_callable()
                   ^^^^^^^^^^^^^^^^^^^^^^^
  File "/home/airflow/.local/lib/python3.12/site-packages/airflow/operators/python.py", line 256, in execute_callable
    return runner.run(*self.op_args, **self.op_kwargs)
           ^^^^^^^^^^^^^^^^^^^^^^^^^^^^^^^^^^^^^^^^^^^
  File "/home/airflow/.local/lib/python3.12/site-packages/airflow/utils/operator_helpers.py", line 252, in run
    return self.func(*args, **kwargs)
           ^^^^^^^^^^^^^^^^^^^^^^^^^^
  File "/opt/airflow/dags/etl_extract_load.py", line 23, in query_public_table
    conn = psycopg2.connect(
           ^^^^^^^^^^^^^^^^^
  File "/home/airflow/.local/lib/python3.12/site-packages/psycopg2/__init__.py", line 122, in connect
    conn = _connect(dsn, connection_factory=connection_factory, **kwasync)
           ^^^^^^^^^^^^^^^^^^^^^^^^^^^^^^^^^^^^^^^^^^^^^^^^^^^^^^^^^^^^^^^
psycopg2.OperationalError: connection to server at "host.docker.internal" (192.168.65.254), port 5432 failed: FATAL:  password authentication failed for user "***"

[2025-04-04T11:25:10.401+0000] {logging_mixin.py:190} INFO - Task instance in failure state
[2025-04-04T11:25:10.401+0000] {logging_mixin.py:190} INFO - Task start:2025-04-04 11:25:09.782920+00:00 end:2025-04-04 11:25:10.400816+00:00 duration:0.617896
[2025-04-04T11:25:10.402+0000] {logging_mixin.py:190} INFO - Task:<Task(PythonOperator): query_public_table> dag:<DAG: et_extract_load> dagrun:<DagRun et_extract_load @ 2025-04-04 11:25:04.300102+00:00: manual__2025-04-04T11:25:04.300102+00:00, state:running, queued_at: 2025-04-04 11:25:04.345291+00:00. externally triggered: True>
[2025-04-04T11:25:10.403+0000] {logging_mixin.py:190} INFO - Failure caused by connection to server at "host.docker.internal" (192.168.65.254), port 5432 failed: FATAL:  password authentication failed for user "***"
[2025-04-04T11:25:10.403+0000] {taskinstance.py:1226} INFO - Marking task as FAILED. dag_id=et_extract_load, task_id=query_public_table, run_id=manual__2025-04-04T11:25:04.300102+00:00, execution_date=20250404T112504, start_date=20250404T112509, end_date=20250404T112510
[2025-04-04T11:25:10.461+0000] {taskinstance.py:341} INFO - ::group::Post task execution logs
[2025-04-04T11:25:10.462+0000] {standard_task_runner.py:124} ERROR - Failed to execute job 35 for task query_public_table (connection to server at "host.docker.internal" (192.168.65.254), port 5432 failed: FATAL:  password authentication failed for user "***"
; 1509)
Traceback (most recent call last):
  File "/home/airflow/.local/lib/python3.12/site-packages/airflow/task/task_runner/standard_task_runner.py", line 117, in _start_by_fork
    ret = args.func(args, dag=self.dag)
          ^^^^^^^^^^^^^^^^^^^^^^^^^^^^^
  File "/home/airflow/.local/lib/python3.12/site-packages/airflow/cli/cli_config.py", line 49, in command
    return func(*args, **kwargs)
           ^^^^^^^^^^^^^^^^^^^^^
  File "/home/airflow/.local/lib/python3.12/site-packages/airflow/utils/cli.py", line 116, in wrapper
    return f(*args, **kwargs)
           ^^^^^^^^^^^^^^^^^^
  File "/home/airflow/.local/lib/python3.12/site-packages/airflow/cli/commands/task_command.py", line 483, in task_run
    task_return_code = _run_task_by_selected_method(args, _dag, ti)
                       ^^^^^^^^^^^^^^^^^^^^^^^^^^^^^^^^^^^^^^^^^^^^
  File "/home/airflow/.local/lib/python3.12/site-packages/airflow/cli/commands/task_command.py", line 256, in _run_task_by_selected_method
    return _run_raw_task(args, ti)
           ^^^^^^^^^^^^^^^^^^^^^^^
  File "/home/airflow/.local/lib/python3.12/site-packages/airflow/cli/commands/task_command.py", line 341, in _run_raw_task
    return ti._run_raw_task(
           ^^^^^^^^^^^^^^^^^
  File "/home/airflow/.local/lib/python3.12/site-packages/airflow/utils/session.py", line 97, in wrapper
    return func(*args, session=session, **kwargs)
           ^^^^^^^^^^^^^^^^^^^^^^^^^^^^^^^^^^^^^^
  File "/home/airflow/.local/lib/python3.12/site-packages/airflow/models/taskinstance.py", line 3006, in _run_raw_task
    return _run_raw_task(
           ^^^^^^^^^^^^^^
  File "/home/airflow/.local/lib/python3.12/site-packages/airflow/models/taskinstance.py", line 274, in _run_raw_task
    TaskInstance._execute_task_with_callbacks(
  File "/home/airflow/.local/lib/python3.12/site-packages/airflow/models/taskinstance.py", line 3161, in _execute_task_with_callbacks
    result = self._execute_task(context, task_orig)
             ^^^^^^^^^^^^^^^^^^^^^^^^^^^^^^^^^^^^^^
  File "/home/airflow/.local/lib/python3.12/site-packages/airflow/models/taskinstance.py", line 3185, in _execute_task
    return _execute_task(self, context, task_orig)
           ^^^^^^^^^^^^^^^^^^^^^^^^^^^^^^^^^^^^^^^
  File "/home/airflow/.local/lib/python3.12/site-packages/airflow/models/taskinstance.py", line 768, in _execute_task
    result = _execute_callable(context=context, **execute_callable_kwargs)
             ^^^^^^^^^^^^^^^^^^^^^^^^^^^^^^^^^^^^^^^^^^^^^^^^^^^^^^^^^^^^^
  File "/home/airflow/.local/lib/python3.12/site-packages/airflow/models/taskinstance.py", line 734, in _execute_callable
    return ExecutionCallableRunner(
           ^^^^^^^^^^^^^^^^^^^^^^^^
  File "/home/airflow/.local/lib/python3.12/site-packages/airflow/utils/operator_helpers.py", line 252, in run
    return self.func(*args, **kwargs)
           ^^^^^^^^^^^^^^^^^^^^^^^^^^
  File "/home/airflow/.local/lib/python3.12/site-packages/airflow/models/baseoperator.py", line 424, in wrapper
    return func(self, *args, **kwargs)
           ^^^^^^^^^^^^^^^^^^^^^^^^^^^
  File "/home/airflow/.local/lib/python3.12/site-packages/airflow/operators/python.py", line 238, in execute
    return_value = self.execute_callable()
                   ^^^^^^^^^^^^^^^^^^^^^^^
  File "/home/airflow/.local/lib/python3.12/site-packages/airflow/operators/python.py", line 256, in execute_callable
    return runner.run(*self.op_args, **self.op_kwargs)
           ^^^^^^^^^^^^^^^^^^^^^^^^^^^^^^^^^^^^^^^^^^^
  File "/home/airflow/.local/lib/python3.12/site-packages/airflow/utils/operator_helpers.py", line 252, in run
    return self.func(*args, **kwargs)
           ^^^^^^^^^^^^^^^^^^^^^^^^^^
  File "/opt/airflow/dags/etl_extract_load.py", line 23, in query_public_table
    conn = psycopg2.connect(
           ^^^^^^^^^^^^^^^^^
  File "/home/airflow/.local/lib/python3.12/site-packages/psycopg2/__init__.py", line 122, in connect
    conn = _connect(dsn, connection_factory=connection_factory, **kwasync)
           ^^^^^^^^^^^^^^^^^^^^^^^^^^^^^^^^^^^^^^^^^^^^^^^^^^^^^^^^^^^^^^^
psycopg2.OperationalError: connection to server at "host.docker.internal" (192.168.65.254), port 5432 failed: FATAL:  password authentication failed for user "***"

[2025-04-04T11:25:10.502+0000] {local_task_job_runner.py:266} INFO - Task exited with return code 1
[2025-04-04T11:25:10.743+0000] {taskinstance.py:3901} INFO - 0 downstream tasks scheduled from follow-on schedule check
[2025-04-04T11:25:10.746+0000] {local_task_job_runner.py:245} INFO - ::endgroup::
